<?xml version="1.0"?>
<robot xmlns:xacro="http://ros.org/wiki/xacro">
  
  <xacro:macro name="link_v0" params="suffix
                                      parent
                                      *joint_origin
                                      *joint_limit">
    <link name="link_${suffix}">
      <visual>
        <origin rpy="${M_PI/2} 0 0"/>
        <geometry>
          <mesh filename="package://motoman_description/meshes/sia20/link_${suffix}/visual.dae"/>
        </geometry>
      </visual>
      <collision>
        <origin rpy="${M_PI/2} 0 0"/>
        <geometry>
          <mesh filename="package://motoman_description/meshes/sia20/link_${suffix}/collision.stl"/>
        </geometry>
      </collision>
    </link>

    <joint name="joint_${suffix}" type="revolute">
      <insert_block name="joint_origin"/>
      <parent link="${parent}"/>
      <child link="link_${suffix}"/>
      <axis xyz="0 0 1"/>
      <dynamics damping="0.7" friction="0.7"/>
      <insert_block name="joint_limit"/>
    </joint>
  </xacro:macro>
</robot>
