<?xml version="1.0" ?>
<!-- =================================================================================== -->
<!-- |    This document was autogenerated by xacro from hc10dt.urdf.xacro              | -->
<!-- |    EDITING THIS FILE BY HAND IS NOT RECOMMENDED                                 | -->
<!-- =================================================================================== -->
<robot name="motoman_motomini" xmlns:xacro="http://ros.org/wiki/xacro">
  <material name="black">
    <color rgba="0.0 0.0 0.0 1.0"/>
  </material>
  <material name="blue">
    <color rgba="0.0 0.0 0.8 1.0"/>
  </material>
  <material name="green">
    <color rgba="0.0 0.8 0.0 1.0"/>
  </material>
  <material name="grey">
    <color rgba="0.2 0.2 0.2 1.0"/>
  </material>
  <material name="orange">
    <color rgba="1.0 0.423529411765 0.0392156862745 1.0"/>
  </material>
  <material name="brown">
    <color rgba="0.870588235294 0.811764705882 0.764705882353 1.0"/>
  </material>
  <material name="red">
    <color rgba="0.8 0.0 0.0 1.0"/>
  </material>
  <material name="white">
    <color rgba="1.0 1.0 1.0 1.0"/>
  </material>
  <link name="base_link">
    <visual>
      <geometry>
        <mesh filename="package://motoman_description/meshes/hc10dt/visual/base_link.dae"/>
      </geometry>
    </visual>
    <collision>
      <geometry>
        <mesh filename="package://motoman_description/meshes/hc10dt/collision/base_link.stl"/>
      </geometry>
    </collision>
    <inertial>
      <mass value="7.884"/>
      <inertia ixx="0.072" ixy="0.000" ixz="0.003" iyy="0.079" iyz="-0.000" izz="0.052"/>
    </inertial>
  </link>
  <link name="world"/>
  <joint name="world" type="fixed">
    <parent link="world"/>
    <child link="base_link"/>
  </joint>
  <link name="link_s">
    <visual>
      <geometry>
        <mesh filename="package://motoman_description/meshes/hc10dt/visual/link_s.dae"/>
      </geometry>
    </visual>
    <collision>
      <geometry>
        <mesh filename="package://motoman_description/meshes/hc10dt/collision/link_s.stl"/>
      </geometry>
    </collision>
    <inertial>
      <mass value="8.913"/>
      <inertia ixx="0.132" ixy="-0.001" ixz="0.001" iyy="0.128" iyz="0.012" izz="0.048"/>
    </inertial>
  </link>
  <joint name="joint_s" type="revolute">
    <origin rpy="0 0 0" xyz="0 0 0.167"/>
    <parent link="base_link"/>
    <child link="link_s"/>
    <axis xyz="0 0 1"/>
    <dynamics dampint="0.7" friction="0.7"/>
    <limit effort="30.0" lower="-3.14159274" upper="3.14159274" velocity="2.26892809"/>
  </joint>
  <link name="link_l">
    <visual>
      <geometry>
        <mesh filename="package://motoman_description/meshes/hc10dt/visual/link_l.dae"/>
      </geometry>
    </visual>
    <collision>
      <geometry>
        <mesh filename="package://motoman_description/meshes/hc10dt/collision/link_l.stl"/>
      </geometry>
    </collision>
    <inertial>
      <mass value="9.260846"/>
      <inertia ixx="2.518" ixy="0.000" ixz="0.000" iyy="0.130" iyz="-0.328" izz="2.418"/>
    </inertial>
  </link>
  <joint name="joint_l" type="revolute">
    <origin rpy="1.57079637 0 0" xyz="0 -0.107 0.108"/>
    <parent link="link_s"/>
    <child link="link_l"/>
    <axis xyz="0 0 1"/>
    <dynamics dampint="0.7" friction="0.7"/>
    <limit effort="30.0" lower="-3.14159274" upper="3.14159274" velocity="2.26892809"/>
  </joint>
  <link name="link_u">
    <visual>
      <geometry>
        <mesh filename="package://motoman_description/meshes/hc10dt/visual/link_u.dae"/>
      </geometry>
    </visual>
    <collision>
      <geometry>
        <mesh filename="package://motoman_description/meshes/hc10dt/collision/link_u.stl"/>
      </geometry>
    </collision>
    <inertial>
      <mass value="9.260846"/>
      <inertia ixx="0.070" ixy="0.001" ixz="-0.004" iyy="0.068" iyz="-0.007" izz="0.025"/>
    </inertial>
  </link>
  <joint name="joint_u" type="revolute">
    <origin rpy="0 0 0" xyz="0 0.7 -0.01"/>
    <parent link="link_l"/>
    <child link="link_u"/>
    <axis xyz="0 0 1"/>
    <dynamics dampint="0.7" friction="0.7"/>
    <limit effort="30.0" lower="-0.087266465" upper="6.195919015" velocity="3.14159274"/>
  </joint>
  <link name="link_r">
    <visual>
      <geometry>
        <mesh filename="package://motoman_description/meshes/hc10dt/visual/link_r.dae"/>
      </geometry>
    </visual>
    <collision>
      <geometry>
        <mesh filename="package://motoman_description/meshes/hc10dt/collision/link_r.stl"/>
      </geometry>
    </collision>
    <inertial>
      <mass value="9.260846"/>
      <inertia ixx="0.347" ixy="0.000" ixz="0.000" iyy="0.347" iyz="0.002" izz="0.007"/>
    </inertial>
  </link>
  <joint name="joint_r" type="revolute">
    <origin rpy="-1.57079637 0 0" xyz="0 -0.106 -0.097"/>
    <parent link="link_u"/>
    <child link="link_r"/>
    <axis xyz="0 0 1"/>
    <dynamics dampint="0.7" friction="0.7"/>
    <limit effort="30.0" lower="-3.14159274" upper="3.14159274" velocity="3.14159274"/>
  </joint>
  <link name="link_b">
    <visual>
      <geometry>
        <mesh filename="package://motoman_description/meshes/hc10dt/visual/link_b.dae"/>
      </geometry>
    </visual>
    <collision>
      <geometry>
        <mesh filename="package://motoman_description/meshes/hc10dt/collision/link_b.stl"/>
      </geometry>
    </collision>
    <inertial>
      <mass value="9.260846"/>
      <inertia ixx="0.074" ixy="0.060" ixz="0.028" iyy="0.000" iyz="0.013" izz="0.000"/>
    </inertial>
  </link>
  <joint name="joint_b" type="revolute">
    <origin rpy="1.57079637 0 0" xyz="0 0.064 -0.393"/>
    <parent link="link_r"/>
    <child link="link_b"/>
    <axis xyz="0 0 1"/>
    <dynamics dampint="0.7" friction="0.7"/>
    <limit effort="30.0" lower="-3.14159274" upper="3.14159274" velocity="4.36332325"/>
  </joint>
  <link name="link_t">
    <visual>
      <geometry>
        <mesh filename="package://motoman_description/meshes/hc10dt/visual/link_t.dae"/>
      </geometry>
    </visual>
    <collision>
      <geometry>
        <mesh filename="package://motoman_description/meshes/hc10dt/collision/link_t.stl"/>
      </geometry>
    </collision>
    <inertial>
      <mass value="9.260846"/>
      <inertia ixx="0.001" ixy="0.000" ixz="0.000" iyy="0.001" iyz="0.000" izz="0.001"/>
    </inertial>
  </link>
  <joint name="joint_t" type="revolute">
    <origin rpy="1.57079637 0 0" xyz="0 -0.1 -0.098"/>
    <parent link="link_b"/>
    <child link="link_t"/>
    <axis xyz="0 0 1"/>
    <dynamics dampint="0.7" friction="0.7"/>
    <limit effort="30.0" lower="-3.14159274" upper="3.14159274" velocity="4.36332325"/>
  </joint>
  <!--   <joint name="joint_tool0" type="fixed">
      <origin rpy="0 0 0" xyz="0 0 0"/>
      <parent link="link_6"/>
      <child link="tool0"/>
    </joint>
   -->
  <transmission name="transmission_1">
    <type>transmission_interface/SimpleTransmission</type>
    <joint name="joint_s">
      <hardwareInterface>PositionJointInterface</hardwareInterface>
    </joint>
    <actuator name="motor_1">
      <hardwareInterface>PositionJointInterface</hardwareInterface>
      <mechanicalReduction>1</mechanicalReduction>
    </actuator>
  </transmission>
  <transmission name="transmission_2">
    <type>transmission_interface/SimpleTransmission</type>
    <joint name="joint_l">
      <hardwareInterface>PositionJointInterface</hardwareInterface>
    </joint>
    <actuator name="motor_2">
      <hardwareInterface>PositionJointInterface</hardwareInterface>
      <mechanicalReduction>1</mechanicalReduction>
    </actuator>
  </transmission>
  <transmission name="transmission_3">
    <type>transmission_interface/SimpleTransmission</type>
    <joint name="joint_u">
      <hardwareInterface>PositionJointInterface</hardwareInterface>
    </joint>
    <actuator name="motor_3">
      <hardwareInterface>PositionJointInterface</hardwareInterface>
      <mechanicalReduction>1</mechanicalReduction>
    </actuator>
  </transmission>
  <transmission name="transmission_4">
    <type>transmission_interface/SimpleTransmission</type>
    <joint name="joint_r">
      <hardwareInterface>PositionJointInterface</hardwareInterface>
    </joint>
    <actuator name="motor_4">
      <hardwareInterface>PositionJointInterface</hardwareInterface>
      <mechanicalReduction>1</mechanicalReduction>
    </actuator>
  </transmission>
  <transmission name="transmission_5">
    <type>transmission_interface/SimpleTransmission</type>
    <joint name="joint_b">
      <hardwareInterface>PositionJointInterface</hardwareInterface>
    </joint>
    <actuator name="motor_5">
      <hardwareInterface>PositionJointInterface</hardwareInterface>
      <mechanicalReduction>1</mechanicalReduction>
    </actuator>
  </transmission>
  <transmission name="transmission_6">
    <type>transmission_interface/SimpleTransmission</type>
    <joint name="joint_t">
      <hardwareInterface>PositionJointInterface</hardwareInterface>
    </joint>
    <actuator name="motor_6">
      <hardwareInterface>PositionJointInterface</hardwareInterface>
      <mechanicalReduction>1</mechanicalReduction>
    </actuator>
  </transmission>
  <!-- gazebo -->
  <gazebo>
    <plugin filename="libgazebo_ros_control.so" name="gazebo_ros_control">
      <robotNamespace>/hc10dt</robotNamespace>
      <robotSimType>gazebo_ros_control/DefaultRobotHWSim</robotSimType>
    </plugin>
  </gazebo>
  <gazebo reference="base_link">
    <mu1>0.2</mu1>
    <mu2>0.2</mu2>
    <selfCollide>true</selfCollide>
  </gazebo>
  <gazebo reference="link_s">
    <mu1>0.2</mu1>
    <mu2>0.2</mu2>
    <selfCollide>true</selfCollide>
  </gazebo>
  <gazebo reference="link_l">
    <mu1>0.2</mu1>
    <mu2>0.2</mu2>
    <selfCollide>true</selfCollide>
  </gazebo>
  <gazebo reference="link_u">
    <mu1>0.2</mu1>
    <mu2>0.2</mu2>
    <selfCollide>true</selfCollide>
  </gazebo>
  <gazebo reference="link_b">
    <mu1>0.2</mu1>
    <mu2>0.2</mu2>
    <selfCollide>true</selfCollide>
  </gazebo>
  <gazebo reference="link_r">
    <mu1>0.2</mu1>
    <mu2>0.2</mu2>
    <selfCollide>true</selfCollide>
  </gazebo>
  <gazebo reference="link_t">
    <mu1>0.2</mu1>
    <mu2>0.2</mu2>
    <selfCollide>true</selfCollide>
  </gazebo>
  <link name="world"/>
  <joint name="world" type="fixed">
    <origin rpy="0 0 0" xyz="0 0 0.067"/>
    <parent link="world"/>
    <child link="base_link"/>
  </joint>
</robot>

